[2025-02-14T21:10:46.951+0000] {local_task_job_runner.py:123} INFO - ::group::Pre task execution logs
[2025-02-14T21:10:46.969+0000] {taskinstance.py:2614} INFO - Dependencies all met for dep_context=non-requeueable deps ti=<TaskInstance: trigger_all_failed_dag.task1 scheduled__2025-02-12T21:33:00+00:00 [queued]>
[2025-02-14T21:10:46.979+0000] {taskinstance.py:2614} INFO - Dependencies all met for dep_context=requeueable deps ti=<TaskInstance: trigger_all_failed_dag.task1 scheduled__2025-02-12T21:33:00+00:00 [queued]>
[2025-02-14T21:10:46.979+0000] {taskinstance.py:2867} INFO - Starting attempt 1 of 1
[2025-02-14T21:10:46.993+0000] {taskinstance.py:2890} INFO - Executing <Task(BashOperator): task1> on 2025-02-12 21:33:00+00:00
[2025-02-14T21:10:46.997+0000] {warnings.py:112} WARNING - /home/***/.local/lib/python3.12/site-packages/***/task/task_runner/standard_task_runner.py:70: DeprecationWarning: This process (pid=302) is multi-threaded, use of fork() may lead to deadlocks in the child.
  pid = os.fork()

[2025-02-14T21:10:46.998+0000] {standard_task_runner.py:72} INFO - Started process 303 to run task
[2025-02-14T21:10:46.999+0000] {standard_task_runner.py:104} INFO - Running: ['***', 'tasks', 'run', 'trigger_all_failed_dag', 'task1', 'scheduled__2025-02-12T21:33:00+00:00', '--job-id', '796', '--raw', '--subdir', 'DAGS_FOLDER/07_trigger_all_failed_dag.py', '--cfg-path', '/tmp/tmpjkrbtuvw']
[2025-02-14T21:10:47.000+0000] {standard_task_runner.py:105} INFO - Job 796: Subtask task1
[2025-02-14T21:10:47.045+0000] {task_command.py:467} INFO - Running <TaskInstance: trigger_all_failed_dag.task1 scheduled__2025-02-12T21:33:00+00:00 [running]> on host ab74d4d90d32
[2025-02-14T21:10:47.125+0000] {taskinstance.py:3134} INFO - Exporting env vars: AIRFLOW_CTX_DAG_OWNER='***' AIRFLOW_CTX_DAG_ID='trigger_all_failed_dag' AIRFLOW_CTX_TASK_ID='task1' AIRFLOW_CTX_EXECUTION_DATE='2025-02-12T21:33:00+00:00' AIRFLOW_CTX_TRY_NUMBER='1' AIRFLOW_CTX_DAG_RUN_ID='scheduled__2025-02-12T21:33:00+00:00'
[2025-02-14T21:10:47.126+0000] {taskinstance.py:732} INFO - ::endgroup::
[2025-02-14T21:10:47.141+0000] {subprocess.py:78} INFO - Tmp dir root location: /tmp
[2025-02-14T21:10:47.142+0000] {subprocess.py:88} INFO - Running command: ['/usr/bin/bash', '-c', 'exit 1']
[2025-02-14T21:10:47.150+0000] {subprocess.py:99} INFO - Output:
[2025-02-14T21:10:47.152+0000] {subprocess.py:110} INFO - Command exited with return code 1
[2025-02-14T21:10:47.163+0000] {taskinstance.py:3313} ERROR - Task failed with exception
Traceback (most recent call last):
  File "/home/airflow/.local/lib/python3.12/site-packages/airflow/models/taskinstance.py", line 768, in _execute_task
    result = _execute_callable(context=context, **execute_callable_kwargs)
             ^^^^^^^^^^^^^^^^^^^^^^^^^^^^^^^^^^^^^^^^^^^^^^^^^^^^^^^^^^^^^
  File "/home/airflow/.local/lib/python3.12/site-packages/airflow/models/taskinstance.py", line 734, in _execute_callable
    return ExecutionCallableRunner(
           ^^^^^^^^^^^^^^^^^^^^^^^^
  File "/home/airflow/.local/lib/python3.12/site-packages/airflow/utils/operator_helpers.py", line 252, in run
    return self.func(*args, **kwargs)
           ^^^^^^^^^^^^^^^^^^^^^^^^^^
  File "/home/airflow/.local/lib/python3.12/site-packages/airflow/models/baseoperator.py", line 424, in wrapper
    return func(self, *args, **kwargs)
           ^^^^^^^^^^^^^^^^^^^^^^^^^^^
  File "/home/airflow/.local/lib/python3.12/site-packages/airflow/operators/bash.py", line 276, in execute
    raise AirflowException(
airflow.exceptions.AirflowException: Bash command failed. The command returned a non-zero exit code 1.
[2025-02-14T21:10:47.167+0000] {taskinstance.py:1226} INFO - Marking task as FAILED. dag_id=trigger_all_failed_dag, task_id=task1, run_id=scheduled__2025-02-12T21:33:00+00:00, execution_date=20250212T213300, start_date=20250214T211046, end_date=20250214T211047
[2025-02-14T21:10:47.191+0000] {taskinstance.py:341} INFO - ::group::Post task execution logs
[2025-02-14T21:10:47.192+0000] {standard_task_runner.py:124} ERROR - Failed to execute job 796 for task task1 (Bash command failed. The command returned a non-zero exit code 1.; 303)
Traceback (most recent call last):
  File "/home/airflow/.local/lib/python3.12/site-packages/airflow/task/task_runner/standard_task_runner.py", line 117, in _start_by_fork
    ret = args.func(args, dag=self.dag)
          ^^^^^^^^^^^^^^^^^^^^^^^^^^^^^
  File "/home/airflow/.local/lib/python3.12/site-packages/airflow/cli/cli_config.py", line 49, in command
    return func(*args, **kwargs)
           ^^^^^^^^^^^^^^^^^^^^^
  File "/home/airflow/.local/lib/python3.12/site-packages/airflow/utils/cli.py", line 116, in wrapper
    return f(*args, **kwargs)
           ^^^^^^^^^^^^^^^^^^
  File "/home/airflow/.local/lib/python3.12/site-packages/airflow/cli/commands/task_command.py", line 483, in task_run
    task_return_code = _run_task_by_selected_method(args, _dag, ti)
                       ^^^^^^^^^^^^^^^^^^^^^^^^^^^^^^^^^^^^^^^^^^^^
  File "/home/airflow/.local/lib/python3.12/site-packages/airflow/cli/commands/task_command.py", line 256, in _run_task_by_selected_method
    return _run_raw_task(args, ti)
           ^^^^^^^^^^^^^^^^^^^^^^^
  File "/home/airflow/.local/lib/python3.12/site-packages/airflow/cli/commands/task_command.py", line 341, in _run_raw_task
    return ti._run_raw_task(
           ^^^^^^^^^^^^^^^^^
  File "/home/airflow/.local/lib/python3.12/site-packages/airflow/utils/session.py", line 97, in wrapper
    return func(*args, session=session, **kwargs)
           ^^^^^^^^^^^^^^^^^^^^^^^^^^^^^^^^^^^^^^
  File "/home/airflow/.local/lib/python3.12/site-packages/airflow/models/taskinstance.py", line 3006, in _run_raw_task
    return _run_raw_task(
           ^^^^^^^^^^^^^^
  File "/home/airflow/.local/lib/python3.12/site-packages/airflow/models/taskinstance.py", line 274, in _run_raw_task
    TaskInstance._execute_task_with_callbacks(
  File "/home/airflow/.local/lib/python3.12/site-packages/airflow/models/taskinstance.py", line 3161, in _execute_task_with_callbacks
    result = self._execute_task(context, task_orig)
             ^^^^^^^^^^^^^^^^^^^^^^^^^^^^^^^^^^^^^^
  File "/home/airflow/.local/lib/python3.12/site-packages/airflow/models/taskinstance.py", line 3185, in _execute_task
    return _execute_task(self, context, task_orig)
           ^^^^^^^^^^^^^^^^^^^^^^^^^^^^^^^^^^^^^^^
  File "/home/airflow/.local/lib/python3.12/site-packages/airflow/models/taskinstance.py", line 768, in _execute_task
    result = _execute_callable(context=context, **execute_callable_kwargs)
             ^^^^^^^^^^^^^^^^^^^^^^^^^^^^^^^^^^^^^^^^^^^^^^^^^^^^^^^^^^^^^
  File "/home/airflow/.local/lib/python3.12/site-packages/airflow/models/taskinstance.py", line 734, in _execute_callable
    return ExecutionCallableRunner(
           ^^^^^^^^^^^^^^^^^^^^^^^^
  File "/home/airflow/.local/lib/python3.12/site-packages/airflow/utils/operator_helpers.py", line 252, in run
    return self.func(*args, **kwargs)
           ^^^^^^^^^^^^^^^^^^^^^^^^^^
  File "/home/airflow/.local/lib/python3.12/site-packages/airflow/models/baseoperator.py", line 424, in wrapper
    return func(self, *args, **kwargs)
           ^^^^^^^^^^^^^^^^^^^^^^^^^^^
  File "/home/airflow/.local/lib/python3.12/site-packages/airflow/operators/bash.py", line 276, in execute
    raise AirflowException(
airflow.exceptions.AirflowException: Bash command failed. The command returned a non-zero exit code 1.
[2025-02-14T21:10:47.213+0000] {local_task_job_runner.py:266} INFO - Task exited with return code 1
[2025-02-14T21:10:47.239+0000] {taskinstance.py:3901} INFO - 1 downstream tasks scheduled from follow-on schedule check
[2025-02-14T21:10:47.240+0000] {local_task_job_runner.py:245} INFO - ::endgroup::
